Workbook

Sheet questoes
A1: ID | B1: DISCIPLINA | C1: TEMA | D1: TOPICO | E1: NIVEL | F1: ENUNCIADO | G1: A | H1: B | I1: C | J1: D | K1: E | L1: CORRETO | M1: CORRETO FORM | N1: GABARITO | O1: FEEDBACK | P1: FONTE | Q1: PAGINA
A2: ECO_T1_001 | B2: Economia | C2: Tema 1 | D2: Introdução à Economia | E2: Ouro | F2: Uma cooperativa agrícola busca melhorar a utilização de máquinas, trabalhadores e matéria-prima para aumentar a eficiência produtiva. Segundo a Economia, qual é o objetivo principal dessa ciência? | G2: Eliminar totalmente a escassez. | H2: Controlar apenas o comércio internacional. | I2: Melhorar a alocação dos recursos para produção de bens e serviços. | J2: Produzir somente bens industriais. | K2: Aumentar o consumo sem planejamento. | L2: C | M2: =_xlfn.XLOOKUP(questoes!$L2,Tabela2[LETRA],Tabela2[IND],"",0) -> 2 | N2: 2 | O2: A Economia é uma ciência social que analisa os sistemas de produção de bens e serviços com o objetivo de proporcionar a melhor alocação dos recursos produtivos disponíveis para atender às necessidades da sociedade. Isso significa utilizar máquinas, trabalhadores, terra, capital e matéria-prima da forma mais eficiente possível. Na prática, uma cooperativa agrícola precisa decidir como utilizar tratores, mão de obra, sementes e fertilizantes sem desperdícios, buscando maior produtividade e melhor resultado econômico. | P2: Tema 1: Princípios de Economia, Tópico 1: Introdução à Economia, Item1: Conceitos básicos, Pág. 10. | Q2: 10
A3: ECO_T1_002 | B3: Economia | C3: Tema 1 | D3: Introdução à Economia | E3: Fácil | F3: O termo “economia” possui origem grega e pode ser traduzido como: | G3: Administração do lar. | H3: Controle da moeda. | I3: Planejamento tributário. | J3: Organização industrial. | K3: Administração pública. | L3: A | M3: =_xlfn.XLOOKUP(questoes!$L3,Tabela2[LETRA],Tabela2[IND],"",0) -> 0 | N3: 0 | O3: O termo “economia” deriva das palavras gregas “oikos” (casa) e “nomos” (costume ou lei), podendo ser traduzido como “administração do lar”. A apostila destaca que a Economia estuda a atividade produtiva e a forma como os recursos são organizados para satisfazer as necessidades humanas. Esse conceito ajuda a compreender que tanto uma família quanto uma empresa precisam administrar recursos limitados para atender suas necessidades. | P3: Tema 1: Princípios de Economia, Tópico 1: Introdução à Economia, Item1: Conceitos básicos, Pág. 10. | Q3: 10
A4: ECO_T1_003 | B4: Economia | C4: Tema 1 | D4: Introdução à Economia | E4: Médio | F4: O principal problema estudado pela Economia está relacionado: | G4: Ao excesso de produtos. | H4: À escassez dos recursos produtivos. | I4: À ausência de consumidores. | J4: À falta de tecnologia. | K4: Ao crescimento industrial. | L4: B | M4: =_xlfn.XLOOKUP(questoes!$L4,Tabela2[LETRA],Tabela2[IND],"",0) -> 1 | N4: 1 | O4: Segundo a apostila, o principal problema estudado pela Economia é a escassez dos recursos produtivos. Enquanto as necessidades humanas são ilimitadas e se renovam constantemente, os recursos disponíveis para produzir bens e serviços são limitados. Isso pode ser observado quando famílias desejam melhorar sua qualidade de vida adquirindo novos bens, como casa, carro, roupas e serviços, mas possuem renda limitada. | P4: Tema 1: Princípios de Economia, Tópico 1: Introdução à Economia, Item1: Conceitos básicos, Pág. 10. | Q4: 10
A5: ECO_T1_004 | B5: Economia | C5: Tema 1 | D5: Introdução à Economia | E5: Fácil | F5: Qual alternativa apresenta exemplos de necessidades humanas citadas na apostila? | G5: Máquinas, tratores e fertilizantes. | H5: Alimentação, moradia e lazer. | I5: PIB, inflação e exportação. | J5: Crédito, juros e impostos. | K5: Comércio exterior e câmbio. | L5: B | M5: =_xlfn.XLOOKUP(questoes!$L5,Tabela2[LETRA],Tabela2[IND],"",0) -> 1 | N5: 1 | O5: A apostila apresenta como exemplos de necessidades humanas a alimentação, educação, moradia, vestuário, transporte, comunicação, lazer e artigos de luxo. Essas necessidades podem ser individuais ou coletivas e são satisfeitas por meio do consumo de bens e serviços. No cotidiano, uma pessoa necessita de alimentação e moradia, mas também busca lazer, comunicação e conforto. | P5: Tema 1: Princípios de Economia, Tópico 1: Introdução à Economia. Pág. 10. | Q5: 10
A6: ECO_T1_005 | B6: Economia | C6: Tema 1 | D6: Introdução à Economia | E6: Médio | F6: Quando uma empresa define quais produtos serão fabricados e em quais quantidades, ela está respondendo à pergunta econômica: | G6: Como produzir? | H6: Para quem produzir? | I6: O que produzir? | J6: Quando produzir? | K6: Quanto exportar? | L6: C | M6: =_xlfn.XLOOKUP(questoes!$L6,Tabela2[LETRA],Tabela2[IND],"",0) -> 2 | N6: 2 | O6: A questão “o que produzir?” está relacionada à escolha dos bens e serviços que serão disponibilizados aos consumidores. | P6: Tema 1: Princípios de Economia, Tópico 1: Introdução à Economia, Item1: Conceitos básicos, Pág. 11. | Q6: 11
A7: ECO_T1_006 | B7: Economia | C7: Tema 1 | D7: Introdução à Economia | E7: Fácil | F7: A escolha da tecnologia utilizada por uma indústria para fabricar seus produtos está relacionada à questão econômica: | G7: Para quem produzir? | H7: Como produzir? | I7: Quanto vender? | J7: Quem consumir? | K7: O que importar? | L7: B | M7: =_xlfn.XLOOKUP(questoes!$L7,Tabela2[LETRA],Tabela2[IND],"",0) -> 1 | N7: 1 | O7: A pergunta “como produzir?” refere-se ao método ou tecnologia utilizada na produção de bens e serviços. | P7: Princípios de Economia, Tópico 1: Introdução à Economia, Item1: Conceitos básicos, Pág. 11. | Q7: 11
A8: ECO_T1_007 | B8: Economia | C8: Tema 1 | D8: Introdução à Economia | E8: Médio | F8: A definição do público consumidor de determinado produto está relacionada à questão econômica: | G8: Como produzir? | H8: Quanto investir? | I8: Quando produzir? | J8: Para quem produzir? | K8: O que exportar? | L8: D | M8: =_xlfn.XLOOKUP(questoes!$L8,Tabela2[LETRA],Tabela2[IND],"",0) -> 3 | N8: 3 | O8: A questão “para quem produzir?” relaciona-se com a definição de quem consumirá os bens e serviços produzidos. | P8: Tema 1: Princípios de Economia, Tópico 1: Introdução à Economia, Item1: Conceitos básicos, Pág. 11. | Q8: 11
A9: ECO_T1_008 | B9: Economia | C9: Tema 1 | D9: Introdução à Economia | E9: Ouro | F9: O estudo do comportamento dos consumidores e empresas em diferentes situações de mercado pertence à: | G9: Macroeconomia. | H9: Economia internacional. | I9: Microeconomia. | J9: Economia financeira. | K9: Economia ambiental. | L9: C | M9: =_xlfn.XLOOKUP(questoes!$L9,Tabela2[LETRA],Tabela2[IND],"",0) -> 2 | N9: 2 | O9: A Microeconomia analisa o comportamento das famílias e empresas nas situações de mercado. No sistema econômico, as famílias participam tanto consumindo produtos quanto oferecendo mão de obra às empresas. | P9: Tema 1: Princípios de Economia, Tópico 1: Introdução à Economia, Item1: Conceitos básicos, Pág. 11. | Q9: 11
A10: ECO_T1_009 | B10: Economia | C10: Tema 1 | D10: Introdução à Economia | E10: Médio | F10: O Produto Interno Bruto (PIB), o nível de emprego e o sistema monetário são estudados principalmente pela: | G10: Microeconomia. | H10: Macroeconomia. | I10: Administração financeira. | J10: Economia rural. | K10: Contabilidade. | L10: B | M10: =_xlfn.XLOOKUP(questoes!$L10,Tabela2[LETRA],Tabela2[IND],"",0) -> 1 | N10: 1 | O10: A Macroeconomia estuda agregados econômicos como PIB, emprego e sistema monetário. | P10: Tema 1: Princípios de Economia, Tópico 1: Introdução à Economia, Item1: Conceitos básicos, Pág. 11. | Q10: 11
A11: ECO_T1_010 | B11: Economia | C11: Tema 1 | D11: Classificação de bens e serviços | E11: Fácil | F11: Bens econômicos são aqueles que: | G11: Possuem oferta ilimitada. | H11: Não exigem trabalho humano. | I11: São escassos e possuem valor de mercado. | J11: Existem apenas no setor industrial. | K11: Não atendem necessidades humanas. | L11: C | M11: =_xlfn.XLOOKUP(questoes!$L11,Tabela2[LETRA],Tabela2[IND],"",0) -> 2 | N11: 2 | O11: Os bens econômicos são relativamente escassos e necessitam de trabalho humano para serem obtidos. | P11: Tema 1: Princípios de Economia, Tópico 1: Introdução à Economia, Item 2: Classificação de bens e serviços. Pág. 11. | Q11: 11
A12: ECO_T1_011 | B12: Economia | C12: Tema 1 | D12: Classificação de bens e serviços | E12: Fácil | F12: Qual alternativa apresenta um exemplo de bem NÃO econômico? | G12: Combustível. | H12: Geladeira. | I12: Ar atmosférico. | J12: Automóvel. | K12: Produto de limpeza. | L12: C | M12: =_xlfn.XLOOKUP(questoes!$L12,Tabela2[LETRA],Tabela2[IND],"",0) -> 2 | N12: 2 | O12: O ar não é considerado um bem econômico porque possui oferta ilimitada e não requer trabalho humano para utilização. . | P12: Tema 1: Princípios de Economia, Tópico 1: Introdução à Economia, Item 2: Classificação de bens e serviços. Pág. 12. | Q12: 12
A13: ECO_T1_012 | B13: Economia | C13: Tema 1 | D13: Classificação de bens e serviços | E13: Fácil | F13: Produtos de limpeza e combustíveis são exemplos de: | G13: Bens de capital. | H13: Bens intermediários. | I13: Bens de consumo não duráveis. | J13: Bens imateriais. | K13: Bens finais duráveis. | L13: C | M13: =_xlfn.XLOOKUP(questoes!$L13,Tabela2[LETRA],Tabela2[IND],"",0) -> 2 | N13: 2 | O13: Bens de consumo não duráveis são utilizados rapidamente, como alimentos, combustíveis e produtos de limpeza. | P13: Tema 1: Princípios de Economia, Tópico 2: Classificação de bens e serviços. Pág. 12. | Q13: 12
A14: ECO_T1_013 | B14: Economia | C14: Tema 1 | D14: Classificação de bens e serviços | E14: Fácil | F14: Automóveis e geladeiras são classificados como: | G14: Bens intermediários. | H14: Bens imateriais. | I14: Bens de capital. | J14: Bens de consumo duráveis. | K14: Bens perecíveis. | L14: D | M14: =_xlfn.XLOOKUP(questoes!$L14,Tabela2[LETRA],Tabela2[IND],"",0) -> 3 | N14: 3 | O14: Bens duráveis podem ser utilizados por um longo período de tempo. | P14: Tema 1: Princípios de Economia, Tópico 2: Classificação de bens e serviços. Pág. 12. | Q14: 12
A15: ECO_T1_014 | B15: Economia | C15: Tema 1 | D15: Classificação de bens e serviços | E15: Médio | F15: Em uma propriedade rural, tratores e implementos agrícolas utilizados na produção são classificados como: | G15: Bens finais. | H15: Bens de capital. | I15: Bens imateriais. | J15: Bens de consumo. | K15: Bens perecíveis. | L15: B | M15: =_xlfn.XLOOKUP(questoes!$L15,Tabela2[LETRA],Tabela2[IND],"",0) -> 1 | N15: 1 | O15: Bens de capital compõem o sistema produtivo e são utilizados para produzir outros bens. | Q15: 11-13
A16: ECO_T1_015 | B16: Economia | C16: Tema 1 | D16: Classificação de bens e serviços | E16: Médio | F16: Os fertilizantes utilizados pelo agricultor para a produção de soja representam: | G16: Bens finais. | H16: Bens imateriais. | I16: Bens intermediários. | J16: Bens duráveis. | K16: Bens de luxo. | L16: C | M16: =_xlfn.XLOOKUP(questoes!$L16,Tabela2[LETRA],Tabela2[IND],"",0) -> 2 | N16: 2 | O16: Bens intermediários são utilizados na produção de outros bens. | P16: Tema 1: Princípios de Economia, Tópico 2: Classificação de bens e serviços. Pág. 11-13. | Q16: 11-13
A17: ECO_T1_016 | B17: Economia | C17: Tema 1 | D17: Classificação de bens e serviços | E17: Fácil | F17: O serviço prestado por um técnico agrícola é considerado um: | G17: Bem de capital. | H17: Bem final. | I17: Bem imaterial. | J17: Bem intermediário. | K17: Bem durável. | L17: C | M17: =_xlfn.XLOOKUP(questoes!$L17,Tabela2[LETRA],Tabela2[IND],"",0) -> 2 | N17: 2 | O17: Os bens imateriais não possuem existência física, como serviços de assistência técnica e educação. | P17: Tema 1: Princípios de Economia, Tópico 2: Classificação de bens e serviços. Pág. 11-13. | Q17: 11-13
A18: ECO_T1_017 | B18: Economia | C18: Tema 1 | D18: Fatores de produção | E18: Médio | F18: Os fatores de produção essenciais utilizados pelas empresas são: | G18: Mercado, moeda e impostos. | H18: Capital, terra e trabalho. | I18: Famílias, empresas e governo. | J18: Máquinas, sementes e fertilizantes. | K18: Oferta, demanda e preço. | L18: B | M18: =_xlfn.XLOOKUP(questoes!$L18,Tabela2[LETRA],Tabela2[IND],"",0) -> 1 | N18: 1 | O18: Os fatores de produção fundamentais são capital, terra e trabalho. | P18: Tema 1: Princípios de Economia, Tópico 3: Fatores de produção. Pág. 13-14. | Q18: 13-14
A19: ECO_T1_018 | B19: Economia | C19: Tema 1 | D19: Fatores de produção | E19: Difícil | F19: Um produtor utiliza um trator para preparar o solo para o plantio de feijão. Nesse caso, o trator representa qual fator de produção? | G19: Trabalho. | H19: Terra. | I19: Capital. | J19: Moeda. | K19: Consumo. | L19: C | M19: =_xlfn.XLOOKUP(questoes!$L19,Tabela2[LETRA],Tabela2[IND],"",0) -> 2 | N19: 2 | O19: Máquinas e equipamentos utilizados no sistema produtivo são classificados como capital. | P19: Tema 1: Princípios de Economia, Tópico 3: Fatores de produção. Pág. 13-14. | Q19: 13-14
A20: ECO_T1_019 | B20: Economia | C20: Tema 1 | D20: Fatores de produção | E20: Fácil | F20: Florestas, recursos minerais e recursos hídricos fazem parte do fator de produção: | G20: Capital. | H20: Terra. | I20: Trabalho. | J20: Tecnologia. | K20: Consumo. | L20: B | M20: =_xlfn.XLOOKUP(questoes!$L20,Tabela2[LETRA],Tabela2[IND],"",0) -> 1 | N20: 1 | O20: O fator terra inclui todos os recursos naturais utilizados nos sistemas produtivos. | P20: Tema 1: Princípios de Economia, Tópico 3: Fatores de produção. Pág. 13-14. | Q20: 13-14
A21: ECO_T1_020 | B21: Economia | C21: Tema 1 | D21: Fatores de produção | E21: Médio | F21: O esforço físico e mental necessário para realizar atividades produtivas corresponde ao fator de produção: | G21: Capital. | H21: Terra. | I21: Mercado. | J21: Trabalho. | K21: Moeda. | L21: D | M21: =_xlfn.XLOOKUP(questoes!$L21,Tabela2[LETRA],Tabela2[IND],"",0) -> 3 | N21: 3 | O21: O fator trabalho consiste na capacidade produtiva das pessoas envolvidas nos sistemas produtivos. | P21: Tema 1: Princípios de Economia, Tópico 3: Fatores de produção. Pág. 13-14. | Q21: 13-14
A22: ECO_T1_021 | B22: Economia | C22: Tema 1 | D22: Agentes econômicos | E22: Fácil | F22: Quais são os agentes econômicos de uma sociedade? | G22: Empresas, bancos e consumidores. | H22: Famílias, empresas e governo. | I22: Mercado, moeda e empresas. | J22: Capital, trabalho e terra. | K22: Indústria, comércio e serviços. | L22: B | M22: =_xlfn.XLOOKUP(questoes!$L22,Tabela2[LETRA],Tabela2[IND],"",0) -> 1 | N22: 1 | O22: Os principais agentes econômicos são famílias, empresas e governo. No sistema econômico, as famílias participam tanto consumindo produtos quanto oferecendo mão de obra às empresas. | P22: Tema 1: Princípios de Economia, Tópico 4: Agentes econômicos. Pág. 14-15. | Q22: 14-15
A23: ECO_T1_022 | B23: Economia | C23: Tema 1 | D23: Agentes econômicos | E23: Médio | F23: Além de consumir bens e serviços, as famílias também têm a função de: | G23: Produzir moeda. | H23: Oferecer recursos produtivos às empresas. | I23: Fiscalizar a economia. | J23: Definir políticas públicas. | K23: Controlar exportações. | L23: B | M23: =_xlfn.XLOOKUP(questoes!$L23,Tabela2[LETRA],Tabela2[IND],"",0) -> 1 | N23: 1 | O23: As famílias oferecem recursos produtivos, especialmente mão de obra, às empresas. No sistema econômico, as famílias participam tanto consumindo produtos quanto oferecendo mão de obra às empresas. | P23: ]Tema 1: Princípios de Economia, Tópico 4: Agentes econômicos. Pág. 14-15. | Q23: 14-15
A24: ECO_T1_023 | B24: Economia | C24: Tema 1 | D24: Agentes econômicos | E24: Médio | F24: A principal função das empresas em um sistema econômico é: | G24: Controlar a inflação. | H24: Produzir e comercializar bens e serviços. | I24: Emitir moeda. | J24: Fiscalizar o mercado. | K24: Regular importações. | L24: B | M24: =_xlfn.XLOOKUP(questoes!$L24,Tabela2[LETRA],Tabela2[IND],"",0) -> 1 | N24: 1 | O24: As empresas produzem e comercializam bens e serviços utilizando fatores de produção. | P24: Tema 1: Princípios de Economia, Tópico 4: Agentes econômicos. Pág. 14-15. | Q24: 14-15
A25: ECO_T1_024 | B25: Economia | C25: Tema 1 | D25: Agentes econômicos | E25: Difícil | F25: As ações do governo relacionadas à fiscalização da economia e provisão de moeda recebem o nome de: | G25: Estratégias privadas. | H25: Políticas públicas. | I25: Atividades comerciais. | J25: Administração empresarial. | K25: Políticas industriais. | L25: B | M25: =_xlfn.XLOOKUP(questoes!$L25,Tabela2[LETRA],Tabela2[IND],"",0) -> 1 | N25: 1 | O25: As ações do governo voltadas ao funcionamento do sistema econômico são chamadas de políticas públicas. | P25: Tema 1: Princípios de Economia, Tópico 4: Agentes econômicos. Pág. 14-15. | Q25: 14-15
A26: ECO_T1_025 | B26: Economia | C26: Tema 1 | D26: Cadeias produtivas do agronegócio brasileiro | E26: Médio | F26: Uma cadeia produtiva pode ser definida como: | G26: Uma atividade industrial isolada. | H26: Um conjunto de operações conectadas técnica, comercial e financeiramente. | I26: Um sistema bancário rural. | J26: Um processo exclusivo da indústria. | K26: Uma política pública agrícola. | L26: B | M26: =_xlfn.XLOOKUP(questoes!$L26,Tabela2[LETRA],Tabela2[IND],"",0) -> 1 | N26: 1 | O26: As cadeias produtivas envolvem operações ligadas por relações técnicas, comerciais e financeiras. No agronegócio, o bom relacionamento entre os agentes econômicos melhora a qualidade dos produtos e reduz desperdícios. | P26: Tema 1: Princípios de Economia, Tópico 5: Cadeias produtivas do agronegócio brasileiro. Pág. 15-18. | Q26: 15-18
A27: ECO_T1_026 | B27: Economia | C27: Tema 1 | D27: Cadeias produtivas do agronegócio brasileiro | E27: Difícil | F27: O estudo das cadeias produtivas do agronegócio permite analisar: | G27: Somente exportações. | H27: Apenas a produção agrícola. | I27: Estratégias, contratos e logística entre agentes econômicos. | J27: Somente preços internacionais. | K27: Exclusivamente impostos rurais. | L27: C | M27: =_xlfn.XLOOKUP(questoes!$L27,Tabela2[LETRA],Tabela2[IND],"",0) -> 2 | N27: 2 | O27: O estudo das cadeias produtivas permite analisar estratégias, contratos, logística e problemas estruturais do agronegócio. No agronegócio, o bom relacionamento entre os agentes econômicos melhora a qualidade dos produtos e reduz desperdícios. | P27: Tema 1: Princípios de Economia, Tópico 5: Cadeias produtivas do agronegócio brasileiro. Pág. 15-18. | Q27: 15-18
... A47: ECO_T1_046 | B47: Economia | C47: Tema 1 | D47: Introdução à Economia | E47: Médio | F47: Segundo a apostila, o Plano Agrícola e Pecuário (PAP) possui como objetivo principal: | G47: Regular apenas exportações. | H47: Definir propostas prioritárias para o agronegócio. | I47: Controlar preços industriais. | J47: Criar impostos municipais. | K47: Fiscalizar supermercados. | L47: B | M47: =_xlfn.XLOOKUP(questoes!$L47,Tabela2[LETRA],Tabela2[IND],"",0) -> 1 | N47: 1 | O47: O PAP estabelece propostas prioritárias para o agronegócio como setor da Economia. | P47: Tema 1: Introdução ao agronegócio. Pág. 10-11. | Q47: 10-11
A48: ECO_T2_001 | B48: Economia | C48: Tema 2 | D48: Estruturas de mercado | E48: Ouro | F48: Uma cooperativa de produtores de hortaliças atua em um mercado com centenas de vendedores e compradores. Os produtos comercializados possuem características semelhantes e nenhum produtor consegue influenciar individualmente os preços praticados. Essa situação caracteriza qual estrutura de mercado? | G48: Monopólio. | H48: Monopsônio. | I48: Oligopólio. | J48: Concorrência perfeita. | K48: Concorrência monopolística. | L48: D | M48: =_xlfn.XLOOKUP(questoes!$L48,Tabela2[LETRA],Tabela2[IND],"",0) -> 3 | N48: 3 | O48: A concorrência perfeita caracteriza-se pela existência de um elevado número de compradores e vendedores, de modo que nenhum agente possui poder para influenciar os preços de mercado. Além disso, os produtos comercializados são homogêneos e funcionam como substitutos perfeitos. O preço é definido pela interação entre oferta e demanda. Os mercados agropecuários frequentemente apresentam características próximas a essa estrutura. | P48: Tema 2: Estudo dos Mercados, Tópico 2: Estruturas de mercado, Item: Concorrência perfeita, Pág. 28. | Q48: 28
A49: ECO_T2_002 | B49: Economia | C49: Tema 2 | D49: Estruturas de mercado | E49: Ouro | F49: Em determinada região, uma grande agroindústria é a única compradora da produção de leite de diversos pecuaristas locais. Mesmo havendo vários produtores, o preço pago pelo produto é definido exclusivamente pela empresa compradora. Essa situação representa qual estrutura de mercado? | G49: Monopólio. | H49: Oligopólio. | I49: Concorrência perfeita. | J49: Concorrência monopolística. | K49: Monopsônio. | L49: E | M49: =_xlfn.XLOOKUP(questoes!$L49,Tabela2[LETRA],Tabela2[IND],"",0) -> 4 | N49: 4 | O49: O monopsônio é a estrutura de mercado em que existe apenas um comprador para diversos vendedores. Nessa situação, o preço do produto ou serviço não é determinado pelos produtores, mas sim pelo único comprador. Esse cenário pode ocorrer quando uma grande empresa se torna a principal ou única demandante de determinado produto ou serviço em uma região, influenciando diretamente as condições de negociação. | P49: Tema 2: Estudo dos Mercados, Tópico 2: Estruturas de mercado, Item: Monopsônio, Pág. 30. | Q49: 30
A50: ECO_T2_003 | B50: Economia | C50: Tema 2 | D50: Estruturas de mercado | E50: Ouro | F50: Os setores automobilístico e de telefonia celular no Brasil apresentam poucas empresas dominando grande parte das vendas. As decisões de preço e produção adotadas por uma empresa afetam diretamente o desempenho das demais concorrentes. Essa estrutura de mercado é denominada: | G50: Monopsônio. | H50: Monopólio. | I50: Concorrência perfeita. | J50: Oligopólio. | K50: Concorrência monopolística. | L50: D | M50: =_xlfn.XLOOKUP(questoes!$L50,Tabela2[LETRA],Tabela2[IND],"",0) -> 3 | N50: 3 | O50: O oligopólio é caracterizado pela presença de poucas empresas que controlam a maior parcela do mercado. Uma de suas principais características é a interdependência entre as firmas, pois as decisões tomadas por uma empresa influenciam o comportamento das demais concorrentes. Além disso, as empresas possuem capacidade de afetar os preços por meio da variação do nível de produção. No Brasil, os setores automobilístico, farmacêutico e de telefonia celular são exemplos de mercados oligopolistas. | P50: Tema 2: Estudo dos Mercados, Tópico 2: Estruturas de mercado, Item: Oligopólio, Pág. 31. | Q50: 31
A51: ECO_T2_004 | B51: Economia | C51: Tema 2 | D51: Estruturas de mercado | E51: Ouro | F51: Qual das alternativas apresenta um exemplo de setor econômico brasileiro que possui características típicas de oligopólio? | G51: Produção de hortaliças. | H51: Serviços de saneamento básico. | I51: Setor de telefonia celular. | J51: Comércio eletrônico de pequenos artesãos. | K51: Feiras livres municipais. | L51: C | M51: =_xlfn.XLOOKUP(questoes!$L51,Tabela2[LETRA],Tabela2[IND],"",0) -> 2 | N51: 2 | O51: Segundo a apostila, o setor de telefonia celular no Brasil é um exemplo de oligopólio, pois poucas empresas concentram a maior parte do mercado. Nessa estrutura, as empresas possuem capacidade de influenciar preços e estratégias comerciais, considerando as ações e reações das concorrentes. | P51: Tema 2: Estudo dos Mercados, Tópico 2: Estruturas de mercado, Item: Oligopólio, Pág. 31. | Q51: 31
A52: ECO_T2_005 | B52: Economia | C52: Tema 2 | D52: Estruturas de mercado | E52: Ouro | F52: Uma das principais características do oligopólio é a interdependência entre as empresas. O que esse conceito significa? | G52: As empresas atuam sem considerar as ações das concorrentes. | H52: As empresas possuem liberdade total para definir preços sem concorrência. | I52: As ações de uma empresa podem afetar o desempenho das demais empresas do mercado. | J52: Existe apenas um comprador para diversos vendedores. | K52: Os produtos são sempre homogêneos e sem diferenciação. | L52: C | M52: =_xlfn.XLOOKUP(questoes!$L52,Tabela2[LETRA],Tabela2[IND],"",0) -> 2 | N52: 2 | O52: Na estrutura de mercado oligopolista, existe interdependência entre as firmas. Isso significa que as decisões de uma empresa, como alterar preços, aumentar a produção ou lançar novos produtos, podem afetar diretamente o desempenho das demais concorrentes. Por esse motivo, as empresas consideram constantemente as possíveis reações dos rivais antes de tomar decisões estratégicas. | P52: Tema 2: Estudo dos Mercados, Tópico 2: Estruturas de mercado, Item: Oligopólio, Pág. 31. | Q52: 31
A53: ECO_T2_006 | B53: Economia | C53: Tema 2 | D53: Estruturas de mercado | E53: Ouro | F53: Em relação à quantidade de empresas atuantes, qual característica define corretamente um mercado oligopolista? | G53: Existe apenas uma empresa vendedora. | H53: Existem muitas empresas sem poder de influenciar preços. | I53: Existe apenas um comprador no mercado. | J53: Existem poucas empresas vendedoras controlando grande parte do mercado. | K53: Existem inúmeras empresas comercializando produtos homogêneos. | L53: D | M53: =_xlfn.XLOOKUP(questoes!$L53,Tabela2[LETRA],Tabela2[IND],"",0) -> 3 | N53: 3 | O53: O oligopólio caracteriza-se pela presença de poucas empresas vendedoras que controlam a maior parcela do mercado. Embora nenhuma delas atue como monopolista, todas possuem capacidade de influenciar o mercado e monitoram constantemente as ações das concorrentes. | P53: Tema 2: Estudo dos Mercados, Tópico 2: Estruturas de mercado, Item: Oligopólio, Pág. 31. | Q53: 31
A54: ECO_T2_007 | B54: Economia | C54: Tema 2 | D54: Estruturas de mercado | E54: Ouro | F54: Em uma cidade, apenas uma empresa é responsável pelo fornecimento de energia elétrica para todos os consumidores locais. Não existem empresas concorrentes e a entrada de novos fornecedores é extremamente difícil devido às barreiras regulatórias e aos elevados investimentos necessários. Essa situação caracteriza qual estrutura de mercado? | G54: Concorrência perfeita. | H54: Oligopólio. | I54: Monopólio. | J54: Monopsônio. | K54: Concorrência monopolística. | L54: C | M54: =_xlfn.XLOOKUP(questoes!$L54,Tabela2[LETRA],Tabela2[IND],"",0) -> 2 | N54: 2 | O54: O monopólio é a estrutura de mercado caracterizada pela presença de apenas uma empresa vendedora, sem concorrentes diretos e com elevadas barreiras à entrada de novas firmas. Nessa situação, a empresa monopolista domina a oferta do mercado e os consumidores ficam sujeitos às condições estabelecidas pelo único fornecedor. Serviços de energia elétrica e saneamento básico são exemplos citados na apostila. | P54: Tema 2: Estudo dos Mercados, Tópico 2: Estruturas de mercado, Item: Monopólio, Pág. 30. | Q54: 30
A55: ECO_T2_008 | B55: Economia | C55: Tema 2 | D55: Estruturas de mercado | E55: Ouro | F55: Qual característica é exclusiva da estrutura de mercado denominada monopólio? | G55: Existência de muitos compradores e vendedores. | H55: Presença de produtos homogêneos e substitutos perfeitos. | I55: Existência de poucas empresas concorrentes. | J55: Presença de um único vendedor sem concorrentes diretos. | K55: Liberdade total para entrada e saída de empresas. | L55: D | M55: =_xlfn.XLOOKUP(questoes!$L55,Tabela2[LETRA],Tabela2[IND],"",0) -> 3 | N55: 3 | O55: A principal característica do monopólio é a unicidade, ou seja, existe apenas uma empresa responsável pela oferta do produto ou serviço no mercado. Além disso, há barreiras à entrada de novos concorrentes e o produto não possui substitutos próximos, permitindo que a empresa monopolista exerça grande influência sobre o mercado. | P55: Tema 2: Estudo dos Mercados, Tópico 2: Estruturas de mercado, Item: Monopólio, Pág. 30. | Q55: 30
A56: ECO_T2_009 | B56: Economia | C56: Tema 2 | D56: Estruturas de mercado | E56: Ouro | F56: Em um centro comercial, diversas empresas vendem sabonetes com fragrâncias, embalagens e marcas diferentes. Apesar das diferenças, os consumidores podem substituir um produto por outro conforme suas preferências. Essa situação representa qual estrutura de mercado? | G56: Monopólio. | H56: Monopsônio. | I56: Concorrência perfeita. | J56: Oligopólio. | K56: Concorrência monopolística. | L56: E | M56: =_xlfn.XLOOKUP(questoes!$L56,Tabela2[LETRA],Tabela2[IND],"",0) -> 4 | N56: 4 | O56: A concorrência monopolística caracteriza-se pela existência de muitas empresas atuando no mercado e pela diferenciação dos produtos. Cada empresa oferece um produto com características próprias, como marca, embalagem ou qualidade, mas os consumidores podem substituí-los por produtos semelhantes oferecidos pelos concorrentes. Os setores de sabonetes e cigarros são exemplos citados na apostila. | P56: Tema 2: Estudo dos Mercados, Tópico 2: Estruturas de mercado, Item: Concorrência monopolística, Pág. 32. | Q56: 32
A57: ECO_T2_010 | B57: Economia | C57: Tema 2 | D57: Estruturas de mercado | E57: Ouro | F57: Na concorrência monopolística, qual característica diferencia essa estrutura da concorrência perfeita? | G57: Existe apenas uma empresa atuando no mercado. | H57: Os produtos comercializados são diferenciados entre si. | I57: Não há liberdade para entrada de novas empresas. | J57: Existe apenas um comprador no mercado. | K57: As empresas não competem entre si. | L57: B | M57: =_xlfn.XLOOKUP(questoes!$L57,Tabela2[LETRA],Tabela2[IND],"",0) -> 1 | N57: 1 | O57: A concorrência monopolística é semelhante à concorrência perfeita por apresentar muitas empresas e liberdade de entrada no mercado. No entanto, diferencia-se porque os produtos e serviços comercializados possuem características próprias, como marca, design ou qualidade, permitindo que cada empresa se destaque dos concorrentes. Apesar disso, esses produtos continuam sendo substituíveis entre si. | P57: Tema 2: Estudo dos Mercados, Tópico 2: Estruturas de mercado, Item: Concorrência monopolística, Pág. 32. | Q57: 32
A58: ECO_T2_011 | C58: Tema 2 | D58: Conceituação de mercado | E58: Ouro | F58: Segundo a Economia, o termo mercado pode ser definido como: | G58: O local físico onde ocorrem apenas vendas de produtos agrícolas. | H58: O conjunto de empresas responsáveis pela produção de bens e serviços. | I58: O local ou as condições em que compradores e vendedores entram em contato para realizar trocas de bens e serviços. | J58: O ambiente virtual utilizado exclusivamente para o comércio eletrônico. | K58: O sistema utilizado pelo governo para controlar preços. | L58: C | M58: =_xlfn.XLOOKUP(questoes!$L58,Tabela2[LETRA],Tabela2[IND],"",0) -> 2 | N58: 2 | O58: Na Economia, mercado é definido como o local ou o conjunto de condições em que compradores dispostos a trocar dinheiro por bens e serviços entram em contato com os vendedores desses mesmos bens e serviços. Esse conceito não se restringe a espaços físicos, podendo incluir ambientes digitais e diferentes formas de negociação. | P58: Tema 2: Estudo dos Mercados, Tópico 1: Conceituação de mercado, Item: Conceito de mercado, Pág. 26. | Q58: 26
A59: ECO_T2_012 | C59: Tema 2 | D59: Conceituação de mercado | E59: Ouro | F59: Quando se afirma que um mercado está em expansão, isso significa que: | G59: Há redução na produção e comercialização de bens e serviços. | H59: Está ocorrendo aumento na produção e na comercialização de bens e serviços. | I59: Os consumidores estão reduzindo seus gastos. | J59: O número de empresas no mercado está diminuindo. | K59: Os preços estão sendo controlados pelo governo. | L59: B | M59: =_xlfn.XLOOKUP(questoes!$L59,Tabela2[LETRA],Tabela2[IND],"",0) -> 1 | N59: 1 | O59: Um mercado em expansão é caracterizado pelo aumento da produção e da comercialização de bens e serviços na economia. Esse cenário geralmente está associado ao crescimento da atividade econômica e à ampliação das oportunidades de negócios. | P59: Tema 2: Estudo dos Mercados, Tópico 1: Conceituação de mercado, Item: Mercado em expansão, Pág. 26. | Q59: 26
...

Sheet Planilha1
A1: LETRA | B1: IND
A2: A | B2: 0
A3: B | B3: 1
A4: C | B4: 2
A5: D | B5: 3
A6: E | B6: 4
